Workbook
Name Slicer_campaign_type: #N/A
Name Slicer_country: #N/A
Name Slicer_industry: #N/A
Name Slicer_platform: #N/A

Sheet Raw_Data 
A1: date | B1: platform | C1: campaign_type | D1: industry | E1: country | F1: impressions | G1: clicks | H1: ad_spend | I1: conversions | J1: revenue
A2: 2024-01-21 | B2: Google Ads | C2: Search | D2: Fintech | E2: UAE | F2: 59886 | G2: 2113 | H2: 2662.38 | I2: 159 | J2: 4803.43
A3: 2024-01-22 | B3: TikTok Ads | C3: Search | D3: EdTech | E3: UK | F3: 135608 | G3: 5220 | H3: 6159.6 | I3: 411 | J3: 64126.68
A4: 2024-06-15 | B4: TikTok Ads | C4: Video | D4: Healthcare | E4: USA | F4: 92313 | G4: 5991 | H4: 5092.35 | I4: 267 | J4: 10489.07
A5: 2024-01-02 | B5: TikTok Ads | C5: Shopping | D5: SaaS | E5: Germany | F5: 83953 | G5: 5935 | H5: 7834.2 | I5: 296 | J5: 50505.07
A6: 2024-02-22 | B6: TikTok Ads | C6: Search | D6: Healthcare | E6: UK | F6: 91807 | G6: 4489 | H6: 8663.77 | I6: 107 | J6: 3369.53
A7: 2024-10-15 | B7: TikTok Ads | C7: Search | D7: Fintech | E7: Canada | F7: 17666 | G7: 724 | H7: 267.88 | I7: 23 | J7: 5220.85
A8: 2024-08-14 | B8: Meta Ads | C8: Video | D8: Fintech | E8: USA | F8: 118252 | G8: 3748 | H8: 1574.16 | I8: 152 | J8: 12838.56
A9: 2024-04-05 | B9: TikTok Ads | C9: Search | D9: EdTech | E9: UAE | F9: 92939 | G9: 5176 | H9: 3416.16 | I9: 388 | J9: 96298.69
A10: 2024-04-17 | B10: Meta Ads | C10: Display | D10: EdTech | E10: Germany | F10: 30939 | G10: 937 | H10: 552.83 | I10: 63 | J10: 16531.03
A11: 2024-11-13 | B11: Google Ads | C11: Shopping | D11: Fintech | E11: USA | F11: 8748 | G11: 362 | H11: 438.02 | I11: 10 | J11: 966.57
A12: 2024-04-22 | B12: Meta Ads | C12: Video | D12: E-commerce | E12: UAE | F12: 98264 | G12: 3144 | H12: 4904.64 | I12: 129 | J12: 23127.27
A13: 2024-09-11 | B13: Meta Ads | C13: Video | D13: Fintech | E13: Canada | F13: 173229 | G13: 5092 | H13: 8758.24 | I13: 65 | J13: 12320.17
... A1801: 2024-01-29 | B1801: Meta Ads | C1801: Display | D1801: EdTech | E1801: UK | F1801: 77447 | G1801: 906 | H1801: 1041.9 | I1801: 29 | J1801: 8284.13

Sheet Cleaned_Data
A1: date | B1: platform | C1: campaign_type | D1: industry | E1: country | F1: impressions | G1: clicks | H1: ad_spend | I1: conversions | J1: revenue | K1: CTR | L1: CPC | M1: CPA | N1: ROAS
A2: 45312 | B2: Google Ads | C2: Search | D2: Fintech | E2: UAE | F2: 59886 | G2: 2113 | H2: 2662.38 | I2: 159 | J2: 4803.43 | K2: =G2 / F2 -> 0.035283706 | L2: =H2/G2 -> 1.26 | M2: =H2/I2 -> 16.744528 | N2: =J2/H2 -> 1.8041865
A3: 45313 | B3: TikTok Ads | C3: Search | D3: EdTech | E3: UK | F3: 135608 | G3: 5220 | H3: 6159.6 | I3: 411 | J3: 64126.68 | K3: =G3 / F3 -> 0.038493304 | L3: =H3/G3 -> 1.18 | M3: =H3/I3 -> 14.986861 | N3: =J3/H3 -> 10.410851
A4: 45458 | B4: TikTok Ads | C4: Video | D4: Healthcare | E4: USA | F4: 92313 | G4: 5991 | H4: 5092.35 | I4: 267 | J4: 10489.07 | K4: =G4 / F4 -> 0.064898768 | L4: =H4/G4 -> 0.85 | M4: =H4/I4 -> 19.072472 | N4: =J4/H4 -> 2.05977
A5: 45293 | B5: TikTok Ads | C5: Shopping | D5: SaaS | E5: Germany | F5: 83953 | G5: 5935 | H5: 7834.2 | I5: 296 | J5: 50505.07 | K5: =G5 / F5 -> 0.070694317 | L5: =H5/G5 -> 1.32 | M5: =H5/I5 -> 26.466892 | N5: =J5/H5 -> 6.4467425
A6: 45344 | B6: TikTok Ads | C6: Search | D6: Healthcare | E6: UK | F6: 91807 | G6: 4489 | H6: 8663.77 | I6: 107 | J6: 3369.53 | K6: =G6 / F6 -> 0.048896054 | L6: =H6/G6 -> 1.93 | M6: =H6/I6 -> 80.969813 | N6: =J6/H6 -> 0.38892191
A7: 45580 | B7: TikTok Ads | C7: Search | D7: Fintech | E7: Canada | F7: 17666 | G7: 724 | H7: 267.88 | I7: 23 | J7: 5220.85 | K7: =G7 / F7 -> 0.040982679 | L7: =H7/G7 -> 0.37 | M7: =H7/I7 -> 11.646957 | N7: =J7/H7 -> 19.48951
A8: 45518 | B8: Meta Ads | C8: Video | D8: Fintech | E8: USA | F8: 118252 | G8: 3748 | H8: 1574.16 | I8: 152 | J8: 12838.56 | K8: =G8 / F8 -> 0.031695024 | L8: =H8/G8 -> 0.42 | M8: =H8/I8 -> 10.356316 | N8: =J8/H8 -> 8.1558164
A9: 45387 | B9: TikTok Ads | C9: Search | D9: EdTech | E9: UAE | F9: 92939 | G9: 5176 | H9: 3416.16 | I9: 388 | J9: 96298.69 | K9: =G9 / F9 -> 0.055692443 | L9: =H9/G9 -> 0.66 | M9: =H9/I9 -> 8.8045361 | N9: =J9/H9 -> 28.189163
A10: 45399 | B10: Meta Ads | C10: Display | D10: EdTech | E10: Germany | F10: 30939 | G10: 937 | H10: 552.83 | I10: 63 | J10: 16531.03 | K10: =G10 / F10 -> 0.0302854 | L10: =H10/G10 -> 0.59 | M10: =H10/I10 -> 8.7750794 | N10: =J10/H10 -> 29.902556
A11: 45609 | B11: Google Ads | C11: Shopping | D11: Fintech | E11: USA | F11: 8748 | G11: 362 | H11: 438.02 | I11: 10 | J11: 966.57 | K11: =G11 / F11 -> 0.041380887 | L11: =H11/G11 -> 1.21 | M11: =H11/I11 -> 43.802 | N11: =J11/H11 -> 2.2066801
A12: 45404 | B12: Meta Ads | C12: Video | D12: E-commerce | E12: UAE | F12: 98264 | G12: 3144 | H12: 4904.64 | I12: 129 | J12: 23127.27 | K12: =G12 / F12 -> 0.031995441 | L12: =H12/G12 -> 1.56 | M12: =H12/I12 -> 38.020465 | N12: =J12/H12 -> 4.7153858
A13: 45546 | B13: Meta Ads | C13: Video | D13: Fintech | E13: Canada | F13: 173229 | G13: 5092 | H13: 8758.24 | I13: 65 | J13: 12320.17 | K13: =G13 / F13 -> 0.029394616 | L13: =H13/G13 -> 1.72 | M13: =H13/I13 -> 134.74215 | N13: =J13/H13 -> 1.4066947
... A1801: 45320 | B1801: Meta Ads | C1801: Display | D1801: EdTech | E1801: UK | F1801: 77447 | G1801: 906 | H1801: 1041.9 | I1801: 29 | J1801: 8284.13 | K1801: =G1801 / F1801 -> 0.011698323 | L1801: =H1801/G1801 -> 1.15 | M1801: =H1801/I1801 -> 35.927586 | N1801: =J1801/H1801 -> 7.9509838

Sheet Pivot_Analysis
A1: Q.1 Avg ROAS by platform | D1: Q.5 Avg ROAS by Country | G1: Q.8 Average CPA by Industry | J1: Q.12 Total Ad_spend by month | M1: Q.14 Total revenue by Month
A2: Platform | B2: Average of ROAS | D2: Country | E2: Average of ROAS | G2: Industry | H2: Average of CPA | J2: Month | K2: Sum of ad_spend | M2: Month | N2: Sum of revenue
A3: TikTok Ads | B3: 9.5385636 | D3: UAE | E3: 6.9618544 | G3: E-commerce | H3: 45.04366 | J3: Jan | K3: 901735.06 | M3: Jan | N3: 4691994.5
A4: Meta Ads | B4: 6.9156663 | D4: Germany | E4: 6.7092945 | G4: SaaS | H4: 45.773213 | J4: Feb | K4: 988588.36 | M4: Feb | N4: 4749203.5
A5: Google Ads | B5: 4.1126934 | D5: Australia | E5: 6.6745505 | G5: Fintech | H5: 46.589138 | J5: Mar | K5: 837915.28 | M5: Mar | N5: 4407519.4
A6: Grand Total | B6: 6.4502015 | D6: India | E6: 6.6494788 | G6: Healthcare | H6: 47.559228 | J6: Apr | K6: 1032895.9 | M6: Apr | N6: 5143463.6
D7: Canada | E7: 6.2579332 | G7: EdTech | H7: 48.038788 | J7: May | K7: 904564.26 | M7: May | N7: 3768913.4
A8: Q.2 Avg CPA by Platform | D8: UK | E8: 6.1449927 | G8: Grand Total | H8: 46.608914 | J8: Jun | K8: 966952.76 | M8: Jun | N8: 4362176.3
A9: Platform | B9: Average of CPA | D9: USA | E9: 5.8089392 | J9: Jul | K9: 797918.14 | M9: Jul | N9: 3695094
A10: TikTok Ads | B10: 29.196644 | D10: Grand Total | E10: 6.4502015 | G10: Q.9 Total revenue by Industry | J10: Aug | K10: 819622.05 | M10: Aug | N10: 4301659.3
A11: Meta Ads | B11: 39.09684 | G11: Industry | H11: Sum of revenue | J11: Sep | K11: 1010523 | M11: Sep | N11: 4749430.3
A12: Google Ads | B12: 64.064647 | D12: Q.6 Average CTR by Country | G12: SaaS | H12: 11891991 | J12: Oct | K12: 868099.26 | M12: Oct | N12: 4670520.7
A13: Grand Total | B13: 46.608914 | D13: Country | E13: Average of CTR | G13: EdTech | H13: 11549934 | J13: Nov | K13: 882564.99 | M13: Nov | N13: 4484002.8
D14: UAE | E14: 0.039463269 | G14: Healthcare | H14: 10930814 | J14: Dec | K14: 1097370 | M14: Dec | N14: 5159353.3
A15: Q.3 Total ad_spend by Platform | D15: Germany | E15: 0.038904772 | G15: Fintech | H15: 10173311 | J15: Grand Total | K15: 11108749 | M15: Grand Total | N15: 54183331
A16: Platform | B16: Sum of ad_spend | D16: USA | E16: 0.03872424 | G16: E-commerce | H16: 9637279.7
A17: Google Ads | B17: 6349268.9 | D17: India | E17: 0.038690794 | G17: Grand Total | H17: 54183331 | J17: Q.13 Average ROAS by Month | M17: Q.15 Avg ROAS by Platform + Country
A18: TikTok Ads | B18: 2653418.5 | D18: Australia | E18: 0.038665769 | J18: Month | K18: Average of ROAS | M18: platform | N18: country | O18: Average of ROAS
A19: Meta Ads | B19: 2106061.7 | D19: Canada | E19: 0.037704694 | G19: Q.10 Avg ROAS by campaign_type | J19: Jan | K19: 6.3190426 | M19: Google Ads | N19: Australia | O19: 3.9360378
A20: Grand Total | B20: 11108749 | D20: UK | E20: 0.036846154 | G20: Campaign Type | H20: Average of ROAS | J20: Feb | K20: 6.1409288 | N20: Canada | O20: 3.5907275
D21: Grand Total | E21: 0.038417417 | G21: Search | H21: 7.0000955 | J21: Mar | K21: 6.1583516 | N21: Germany | O21: 3.8402688
A22: Q.4 Total revenue by Country | G22: Display | H22: 6.4485482 | J22: Apr | K22: 6.819044 | N22: India | O22: 4.0169652
A23: Country | B23: Sum of revenue | D23: Q.7 Total conversions by Industry | G23: Video | H23: 6.3397924 | J23: May | K23: 6.1692708 | N23: UAE | O23: 4.7678783
A24: UAE | B24: 7939594.4 | D24: Industry | E24: Sum of conversions | G24: Shopping | H24: 5.9775872 | J24: Jun | K24: 5.7784112 | N24: UK | O24: 4.5080524
A25: Australia | B25: 7921847.8 | D25: SaaS | E25: 71261 | G25: Grand Total | H25: 6.4502015 | J25: Jul | K25: 6.163109 | N25: USA | O25: 4.0101333
A26: India | B26: 7909606.3 | D26: EdTech | E26: 67257 | J26: Aug | K26: 6.7201477 | M26: Google Ads Total | O26: 4.1126934
A27: Canada | B27: 7867323.1 | D27: Healthcare | E27: 65687 | G27: Q.11 Avg CTR by campaign_type | J27: Sep | K27: 6.1642259 | M27: Meta Ads | N27: Australia | O27: 8.0039335
A28: Germany | B28: 7694838.6 | D28: Fintech | E28: 65121 | G28: Campaign Type | H28: Average of CTR | J28: Oct | K28: 7.0987031 | N28: Canada | O28: 6.1649925
A29: UK | B29: 7659544.3 | D29: E-commerce | E29: 57486 | G29: Search | H29: 0.039415661 | J29: Nov | K29: 6.6932358 | N29: Germany | O29: 7.4694315
A30: USA | B30: 7190576.3 | D30: Grand Total | E30: 326812 | G30: Shopping | H30: 0.038479229 | J30: Dec | K30: 7.1726688 | N30: India | O30: 6.6746081
A31: Grand Total | B31: 54183331 | G31: Display | H31: 0.038082171 | J31: Grand Total | K31: 6.4502015 | N31: UAE | O31: 8.7771085
G32: Video | H32: 0.037621388 | N32: UK | O32: 5.8917513
G33: Grand Total | H33: 0.038417417 | N33: USA | O33: 6.1374941
M34: Meta Ads Total | O34: 6.9156663
M35: TikTok Ads | N35: Australia | O35: 10.014414
N36: Canada | O36: 10.185823
N37: Germany | O37: 9.735683
N38: India | O38: 9.9453313
N39: UAE | O39: 9.052212
N40: UK | O40: 9.196358
...

Sheet Dashboard
B1: Marketing Campaign Performance Dashboard - 2024
B4: Total Ad Spend | F4: Total Revenue | J4: Overall ROAS | N4: Total Conversions | R4: Overall CTR
B5: =GETPIVOTDATA("Sum of ad_spend",Pivot_Analysis!$B$200) -> 11108749 | F5: =GETPIVOTDATA("Sum of revenue",Pivot_Analysis!$B$200) -> 54183331 | J5: =GETPIVOTDATA("Sum of revenue",Pivot_Analysis!$B$200) / GETPIVOTDATA("Sum of ad_spend",Pivot_Analysis!$B$200) -> 4.8775366 | N5: =GETPIVOTDATA("Sum of conversions",Pivot_Analysis!$B$200) -> 326812 | R5: =GETPIVOTDATA("Sum of clicks",Pivot_Analysis!$B$200)/GETPIVOTDATA("Sum of impressions",Pivot_Analysis!$B$200) -> 0.03850285

Sheet Insights
B1: Key Insights & Recommendations
